Workbook

Sheet LEIA-ME
A1: SANDLAND / PLANO DE IMPLEMENTAÇÃO
A4: Modelo de trabalho | B4: Uma pessoa responsável + agentes de IA; WIP principal recomendado = 1.
A5: Cadência | B5: Sprints por aceite, sem duração fixa. Não converter 72 sprints em 144 semanas.
A6: Horizonte | B6: v1.0 completa; v1.1 maturação; v1.2/v2.0 evoluções propostas com ADRs explícitas.
A7: Escala do plano | B7: 72 sprints; 720 tarefas; 72 gates; 19 versões; 37 requisitos; 18 ADRs.
A8: Estado inicial | B8: Planejamento. Nenhuma implementação, benchmark ou homologação do app foi realizada nesta entrega.
A9: Como começar | B9: Abra Tarefas, filtre Sprint = S01 e siga SL-S01-01. Feche o gate somente com evidência e revisão humana.
A10: Colunas editáveis | B10: Status, Responsável, Revisor humano, Data de aceite, Evidência obtida, ADR/justificativa e Observações.
A11: Fechamento | B11: OK exige Concluído + revisor + data + evidência + dependências fechadas. PREENCHER CAMPOS NÃO PROVA A EVIDÊNCIA.
A12: Dispensas | B12: Somente itens condicionais podem usar Dispensado (ADR), com justificativa/evidência/revisão. Invariantes essenciais não são dispensáveis.
A13: Fórmulas | B13: Recalculadas ao abrir em Excel/LibreOffice. Previews podem não calcular fórmulas. Use o status inicial como planejado, não como progresso certificado.
A14: Dependências | B14: IDs no nível de tarefa/gate. Ordem numérica é rota solo recomendada; dependências técnicas de sprints estão na aba Sprints.
A15: Artefatos | B15: Caminhos listados são saídas futuras no repositório do app. Evidência exigida não significa evidência já produzida.
... A23: Base | B23: RFC do autor e Sandland-RFC-Integracao-e-Desconstrucao.md, preservados sem alteração.

Sheet Painel
A1: SANDLAND / VISÃO DO ROADMAP
A4: Sprints planejados | E4: 72
A5: Tarefas detalhadas | E5: 720
A6: Gates humanos | E6: 72
A7: Versões/marcos | E7: 19
A8: Requisitos rastreados | E8: 37
A9: ADRs a decidir | E9: 18
A10: Tarefas com fechamento válido | E10: =COUNTIFS(Tarefas!$G$2:$G$793,"<>Gate",Tarefas!$X$2:$X$793,"OK")
A11: Gates com fechamento válido | E11: =COUNTIFS(Tarefas!$G$2:$G$793,"Gate",Tarefas!$X$2:$X$793,"OK")
A12: Itens que exigem revisão | E12: =COUNTIF(Tarefas!$X$2:$X$793,"REVISAR")
A14: Estado de entrega: plano, não implementação. Todos os itens começam Não iniciado. Contagem de tarefas não mede horas, semanas ou dificuldade. Fórmulas exigem recálculo no editor de planilhas e não validam a veracidade das evidências.
A18: Abrir Tarefas
A19: Abrir Sprints
A20: Abrir Versões
A21: Abrir Motores
A22: Abrir Requisitos
A23: Abrir ADRs
A24: Abrir Gates
A25: Abrir Riscos
A26: Abrir Dependências

Sheet Tarefas
A1: Ordem | B1: ID | C1: Versão | D1: Sprint | E1: Componente | F1: Forma de integração | G1: Tipo | H1: Tarefa | I1: Passo de execução | J1: Artefato a produzir | K1: Critério de aceite | L1: Dependências | M1: Requisitos | N1: Status | O1: Prioridade na versão | P1: Risco | Q1: Aplicabilidade | R1: Responsável | S1: Revisor humano | T1: Data de aceite | U1: Evidência exigida | V1: Evidência obtida | W1: ADR / justificativa | X1: Fechamento | Y1: Observações
A2: 1 | B2: SL-S01-01 | C2: v0.0.1 | D2: S01 | E2: Arquitetura / produto | F2: Próprio | G2: Decisão | H2: Congelar documentos de entrada | I2: Copiar RFC e plano de integração para referências; registrar hashes e divergências. | J2: docs/baseline/manifest.json | K2: Os dois documentos permanecem íntegros e cada divergência aponta à seção de origem. | M2: R01; R03; R07; R08; R33; R34 | N2: Não iniciado | O2: P0 | P2: Crítico | Q2: Obrigatória no escopo da versão | R2: Autor | U2: reports/S01/SL-S01-01.md | X2: =IF(N2="Concluído",IF(AND(S2<>"",ISNUMBER(T2),T2>0,V2<>"",TRUE),"OK","REVISAR"),IF(N2="Dispensado (ADR)",IF(AND(LEFT(Q2,11)="Condicional",W2<>"",S2<>"",ISNUMBER(T2),T2>0,V2<>""),"DISPENSADO","REVISAR"),"PENDENTE"))
A3: 2 | B3: SL-S01-02 | C3: v0.0.1 | D3: S01 | E3: Arquitetura / produto | F3: Próprio | G3: Decisão | H3: Delimitar v1.0 | I3: Enumerar jornadas Captura→Mesa→Peça e separar requisitos de propostas pós-v1.0. | J3: docs/product/scope-v1.md | K3: Nenhuma funcionalidade original é silenciosamente adiada para v2; exclusões estão explícitas. | L3: SL-S01-01 | M3: R01; R03; R07; R08; R33; R34 | N3: Não iniciado | O3: P0 | P3: Crítico | Q3: Obrigatória no escopo da versão | R3: Autor | U3: reports/S01/SL-S01-02.md | X3: =IF(N3="Concluído",IF(AND(S3<>"",ISNUMBER(T3),T3>0,V3<>"",AND(OR(X2="OK",X2="DISPENSADO"))),"OK","REVISAR"),IF(N3="Dispensado (ADR)",IF(AND(LEFT(Q3,11)="Condicional",W3<>"",S3<>"",ISNUMBER(T3),T3>0,V3<>""),"DISPENSADO","REVISAR"),"PENDENTE"))
A4: 3 | B4: SL-S01-03 | C4: v0.0.1 | D4: S01 | E4: Arquitetura / produto | F4: Próprio | G4: Decisão | H4: Ratificar núcleo e workers | I4: Resolver ADR-001; distinguir linguagem do Core, runtime e modelo de distribuição. | J4: docs/adr/001-composicao.md | K4: Decisão aprovada pelo autor; rejeição de workers bloqueia o restante e exige novo plano. | L4: SL-S01-02 | M4: R01; R03; R07; R08; R33; R34 | N4: Não iniciado | O4: P0 | P4: Crítico | Q4: Obrigatória no escopo da versão | R4: Autor | U4: reports/S01/SL-S01-03.md | X4: =IF(N4="Concluído",IF(AND(S4<>"",ISNUMBER(T4),T4>0,V4<>"",AND(OR(X3="OK",X3="DISPENSADO"))),"OK","REVISAR"),IF(N4="Dispensado (ADR)",IF(AND(LEFT(Q4,11)="Condicional",W4<>"",S4<>"",ISNUMBER(T4),T4>0,V4<>""),"DISPENSADO","REVISAR"),"PENDENTE"))
A5: 4 | B5: SL-S01-04 | C5: v0.0.1 | D5: S01 | E5: Arquitetura / produto | F5: Próprio | G5: Decisão | H5: Ratificar Jev/offline | I5: Escolher fallback local ou pendência; definir quando a API pode receber conteúdo. | J5: docs/adr/004-egress-offline.md | K5: Falta de chave/rede não bloqueia captura, leitura ou autoria; nenhuma chamada implícita permitida. | L5: SL-S01-03 | M5: R01; R03; R07; R08; R33; R34 | N5: Não iniciado | O5: P0 | P5: Crítico | Q5: Obrigatória no escopo da versão | R5: Autor | U5: reports/S01/SL-S01-04.md | X5: =IF(N5="Concluído",IF(AND(S5<>"",ISNUMBER(T5),T5>0,V5<>"",AND(OR(X4="OK",X4="DISPENSADO"))),"OK","REVISAR"),IF(N5="Dispensado (ADR)",IF(AND(LEFT(Q5,11)="Condicional",W5<>"",S5<>"",ISNUMBER(T5),T5>0,V5<>""),"DISPENSADO","REVISAR"),"PENDENTE"))
A6: 5 | B6: SL-S01-05 | C6: v0.0.1 | D6: S01 | E6: Arquitetura / produto | F6: Próprio | G6: Decisão | H6: Escolher host de referência | I6: Registrar máquina principal e acesso de teste aos cinco alvos previstos. | J6: docs/adr/006-targets.md | K6: Plataforma de desenvolvimento escolhida e lacunas de hardware identificadas, sem alegar homologação. | L6: SL-S01-04 | M6: R01; R03; R07; R08; R33; R34 | N6: Não iniciado | O6: P0 | P6: Crítico | Q6: Obrigatória no escopo da versão | R6: Autor | U6: reports/S01/SL-S01-05.md | X6: =IF(N6="Concluído",IF(AND(S6<>"",ISNUMBER(T6),T6>0,V6<>"",AND(OR(X5="OK",X5="DISPENSADO"))),"OK","REVISAR"),IF(N6="Dispensado (ADR)",IF(AND(LEFT(Q6,11)="Condicional",W6<>"",S6<>"",ISNUMBER(T6),T6>0,V6<>""),"DISPENSADO","REVISAR"),"PENDENTE"))
A7: 6 | B7: SL-S01-06 | C7: v0.0.1 | D7: S01 | E7: Arquitetura / produto | F7: Próprio | G7: Decisão | H7: Fixar semântica de versões | I7: Separar versão do app, formato do Vault, contratos de workers e modelos. | J7: docs/product/version-policy.md | K7: Atualizar o app não implica migrar o Vault; regras pre-1.0 e compatibilidade estão claras. | L7: SL-S01-05 | M7: R01; R03; R07; R08; R33; R34 | N7: Não iniciado | O7: P0 | P7: Crítico | Q7: Obrigatória no escopo da versão | R7: Autor | U7: reports/S01/SL-S01-06.md | X7: =IF(N7="Concluído",IF(AND(S7<>"",ISNUMBER(T7),T7>0,V7<>"",AND(OR(X6="OK",X6="DISPENSADO"))),"OK","REVISAR"),IF(N7="Dispensado (ADR)",IF(AND(LEFT(Q7,11)="Condicional",W7<>"",S7<>"",ISNUMBER(T7),T7>0,V7<>""),"DISPENSADO","REVISAR"),"PENDENTE"))
A8: 7 | B8: SL-S01-07 | C8: v0.0.1 | D8: S01 | E8: Arquitetura / produto | F8: Próprio | G8: Decisão | H8: Definir dados sensíveis | I8: Classificar conteúdo, consultas, metadados, chaves e logs; negar envio por padrão. | J8: docs/security/data-classification.md | K8: Casos de resumo e título sensível também exigem política de saída, não apenas documentos completos. | L8: SL-S01-06 | M8: R01; R03; R07; R08; R33; R34 | N8: Não iniciado | O8: P0 | P8: Crítico | Q8: Obrigatória no escopo da versão | R8: Autor | U8: reports/S01/SL-S01-07.md | X8: =IF(N8="Concluído",IF(AND(S8<>"",ISNUMBER(T8),T8>0,V8<>"",AND(OR(X7="OK",X7="DISPENSADO"))),"OK","REVISAR"),IF(N8="Dispensado (ADR)",IF(AND(LEFT(Q8,11)="Condicional",W8<>"",S8<>"",ISNUMBER(T8),T8>0,V8<>""),"DISPENSADO","REVISAR"),"PENDENTE"))
A9: 8 | B9: SL-S01-08 | C9: v0.0.1 | D9: S01 | E9: Arquitetura / produto | F9: Próprio | G9: Decisão | H9: Mapear atores e ameaças | I9: Incluir arquivo malformado, página hostil, extensão, modelo e processo local malicioso. | J9: docs/security/threat-model.md | K9: Cada ator tem ativos, fronteiras e ataques de teste; modelo não aparece como autoridade confiável. | L9: SL-S01-07 | M9: R01; R03; R07; R08; R33; R34 | N9: Não iniciado | O9: P0 | P9: Crítico | Q9: Obrigatória no escopo da versão | R9: Autor | U9: reports/S01/SL-S01-08.md | X9: =IF(N9="Concluído",IF(AND(S9<>"",ISNUMBER(T9),T9>0,V9<>"",AND(OR(X8="OK",X8="DISPENSADO"))),"OK","REVISAR"),IF(N9="Dispensado (ADR)",IF(AND(LEFT(Q9,11)="Condicional",W9<>"",S9<>"",ISNUMBER(T9),T9>0,V9<>""),"DISPENSADO","REVISAR"),"PENDENTE"))
A10: 9 | B10: SL-S01-09 | C10: v0.0.1 | D10: S01 | E10: Arquitetura / produto | F10: Próprio | G10: Decisão | H10: Registrar não escopo | I10: Excluir SaaS obrigatório, colaboração em tempo real e marketplace irrestrito deste horizonte. | J10: docs/product/non-goals.md | K10: Funcionalidades não aprovadas não entram por implicação da presença de Yjs, LocalAI ou MCP. | L10: SL-S01-08 | M10: R01; R03; R07; R08; R33; R34 | N10: Não iniciado | O10: P0 | P10: Crítico | Q10: Obrigatória no escopo da versão | R10: Autor | U10: reports/S01/SL-S01-09.md | X10: =IF(N10="Concluído",IF(AND(S10<>"",ISNUMBER(T10),T10>0,V10<>"",AND(OR(X9="OK",X9="DISPENSADO"))),"OK","REVISAR"),IF(N10="Dispensado (ADR)",IF(AND(LEFT(Q10,11)="Condicional",W10<>"",S10<>"",ISNUMBER(T10),T10>0,V10<>""),"DISPENSADO","REVISAR"),"PENDENTE"))
A11: 10 | B11: SL-S01-10 | C11: v0.0.1 | D11: S01 | E11: Arquitetura / produto | F11: Próprio | G11: Decisão | H11: Aprovar inventário de requisitos | I11: Numerar invariantes, métricas e critérios; designar o autor como aprovador dos gates. | J11: docs/product/requirements.yaml | K11: Cada requisito tem origem, critério e responsável; ambiguidades não são tratadas como concluídas. | L11: SL-S01-09 | M11: R01; R03; R07; R08; R33; R34 | N11: Não iniciado | O11: P0 | P11: Crítico | Q11: Obrigatória no escopo da versão | R11: Autor | U11: reports/S01/SL-S01-10.md | X11: =IF(N11="Concluído",IF(AND(S11<>"",ISNUMBER(T11),T11>0,V11<>"",AND(OR(X10="OK",X10="DISPENSADO"))),"OK","REVISAR"),IF(N11="Dispensado (ADR)",IF(AND(LEFT(Q11,11)="Condicional",W11<>"",S11<>"",ISNUMBER(T11),T11>0,V11<>""),"DISPENSADO","REVISAR"),"PENDENTE"))
A12: 11 | B12: SL-S01-GATE | C12: v0.0.1 | D12: S01 | E12: Arquitetura / produto | F12: Aceite humano | G12: Gate | H12: Aceitar S01 — Ratificar escopo, soberania e composição | I12: Revisar as dez tarefas, executar a demonstração do sprint, confrontar critérios e registrar decisão go/no-go. | J12: reports/S01/acceptance.md | K12: Autor consegue explicar offline, Jev, workers e cinco alvos sem contradições. Todas as dependências aceitas; evidências vinculadas a revisão/ambiente; nenhum blocker de integridade/segurança. | L12: SL-S01-01; SL-S01-02; SL-S01-03; SL-S01-04; SL-S01-05; SL-S01-06; SL-S01-07; SL-S01-08; SL-S01-09; SL-S01-10 | M12: R01; R03; R07; R08; R33; R34 | N12: Não iniciado | O12: P0 | P12: Crítico | Q12: Obrigatória para fechar a versão aprovada | R12: Autor | U12: reports/S01/acceptance.md | X12: =IF(N12="Concluído",IF(AND(S12<>"",ISNUMBER(T12),T12>0,V12<>"",AND(OR(X2="OK",X2="DISPENSADO"),OR(X3="OK",X3="DISPENSADO"),OR(X4="OK",X4="DISPENSADO"),OR(X5="OK",X5="DISPENSADO"),OR(X6="OK",X6="DISPENSADO"),OR(X7="OK",X7="DISPENSADO"),OR(X8="OK",X8="DISPENSADO"),OR(X9="OK",X9="DISPENSADO"),OR(X10="OK",X10="DISPENSADO"),OR(X11="OK",X11="DISPENSADO"))),"OK","REVISAR"),IF(N12="Dispensado (ADR)",IF(AND(LEFT(Q12,11)="Condicional",W12<>"",S12<>"",ISNUMBER(T12),T12>0,V12<>""),"DISPENSADO","REVISAR"),"PENDENTE"))
A13: 12 | B13: SL-S02-01 | C13: v0.0.1 | D13: S02 | E13: Vault / contratos | F13: Próprio | G13: Contrato | H13: Definir entidade e ocorrência | I13: Separar fonte, conteúdo da célula/nota, ocorrência visual, grupo, aresta, Peça e bloco. | J13: schemas/domain-v0.json | K13: A mesma nota em dois boards tem conteúdo único e duas geometrias independentes. | L13: SL-S01-GATE | M13: R02; R04; R05; R11; R13; R32; R37 | N13: Não iniciado | O13: P0 | P13: Crítico | Q13: Obrigatória no escopo da versão | R13: Autor + agente de IA | U13: reports/S02/SL-S02-01.md | X13: =IF(N13="Concluído",IF(AND(S13<>"",ISNUMBER(T13),T13>0,V13<>"",AND(OR(X12="OK",X12="DISPENSADO"))),"OK","REVISAR"),IF(N13="Dispensado (ADR)",IF(AND(LEFT(Q13,11)="Condicional",W13<>"",S13<>"",ISNUMBER(T13),T13>0,V13<>""),"DISPENSADO","REVISAR"),"PENDENTE"))
A14: 13 | B14: SL-S02-02 | C14: v0.0.1 | D14: S02 | E14: Vault / contratos | F14: Próprio | G14: Contrato | H14: Definir IDs estáveis | I14: Fixar geração, namespace e regras de colisão sem depender do nome do arquivo. | J14: schemas/identity-v0.json | K14: Renomear/mover não altera identidade; duplicar como nova autoria recebe novo ID. | L14: SL-S02-01 | M14: R02; R04; R05; R11; R13; R32; R37 | N14: Não iniciado | O14: P0 | P14: Crítico | Q14: Obrigatória no escopo da versão | R14: Autor + agente de IA | U14: reports/S02/SL-S02-02.md | X14: =IF(N14="Concluído",IF(AND(S14<>"",ISNUMBER(T14),T14>0,V14<>"",AND(OR(X13="OK",X13="DISPENSADO"))),"OK","REVISAR"),IF(N14="Dispensado (ADR)",IF(AND(LEFT(Q14,11)="Condicional",W14<>"",S14<>"",ISNUMBER(T14),T14>0,V14<>""),"DISPENSADO","REVISAR"),"PENDENTE"))
A15: 14 | B15: SL-S02-03 | C15: v0.0.1 | D15: S02 | E15: Vault / contratos | F15: Próprio | G15: Decisão | H15: Definir autoridade de arquivos | I15: Formalizar JSON+histórico e MPK derivado; resolver ADR-002. | J15: docs/adr/002-file-truth.md | K15: Recuperação tem precedência determinística e não escolhe fonte por timestamp arbitrário. | L15: SL-S02-02 | M15: R02; R04; R05; R11; R13; R32; R37 | N15: Não iniciado | O15: P0 | P15: Crítico | Q15: Obrigatória no escopo da versão | R15: Autor | U15: reports/S02/SL-S02-03.md | X15: =IF(N15="Concluído",IF(AND(S15<>"",ISNUMBER(T15),T15>0,V15<>"",AND(OR(X14="OK",X14="DISPENSADO"))),"OK","REVISAR"),IF(N15="Dispensado (ADR)",IF(AND(LEFT(Q15,11)="Condicional",W15<>"",S15<>"",ISNUMBER(T15),T15>0,V15<>""),"DISPENSADO","REVISAR"),"PENDENTE"))
A16: 15 | B16: SL-S02-04 | C16: v0.0.1 | D16: S02 | E16: Vault / contratos | F16: Próprio | G16: Contrato | H16: Especificar perfil Markdown | I16: Listar blocos suportados e representação de frontmatter, IDs, tabelas e citações. | J16: docs/adr/005-markdown-profile.md | K16: Cada bloco possui round-trip previsto; recurso não representável é preservado ou recusado, não achatado. | L16: SL-S02-03 | M16: R02; R04; R05; R11; R13; R32; R37 | N16: Não iniciado | O16: P0 | P16: Crítico | Q16: Obrigatória no escopo da versão | R16: Autor + agente de IA | U16: reports/S02/SL-S02-04.md | X16: =IF(N16="Concluído",IF(AND(S16<>"",ISNUMBER(T16),T16>0,V16<>"",AND(OR(X15="OK",X15="DISPENSADO"))),"OK","REVISAR"),IF(N16="Dispensado (ADR)",IF(AND(LEFT(Q16,11)="Condicional",W16<>"",S16<>"",ISNUMBER(T16),T16>0,V16<>""),"DISPENSADO","REVISAR"),"PENDENTE"))
A17: 16 | B17: SL-S02-05 | C17: v0.0.1 | D17: S02 | E17: Vault / contratos | F17: Próprio | G17: Contrato | H17: Especificar topologia | I17: Registrar posições, dimensões, grupos, conexões, rótulos e referências de conteúdo. | J17: schemas/board-v0.json | K17: Ciclos e arestas entre grupos são representáveis sem duplicar conteúdo. | L17: SL-S02-04 | M17: R02; R04; R05; R11; R13; R32; R37 | N17: Não iniciado | O17: P0 | P17: Crítico | Q17: Obrigatória no escopo da versão | R17: Autor + agente de IA | U17: reports/S02/SL-S02-05.md | X17: =IF(N17="Concluído",IF(AND(S17<>"",ISNUMBER(T17),T17>0,V17<>"",AND(OR(X16="OK",X16="DISPENSADO"))),"OK","REVISAR"),IF(N17="Dispensado (ADR)",IF(AND(LEFT(Q17,11)="Condicional",W17<>"",S17<>"",ISNUMBER(T17),T17>0,V17<>""),"DISPENSADO","REVISAR"),"PENDENTE"))
A18: 17 | B18: SL-S02-06 | C18: v0.0.1 | D18: S02 | E18: Vault / contratos | F18: Próprio | G18: Contrato | H18: Especificar revisões e eventos | I18: Definir base_revision, operação, autor, origem IA e marcador de confirmação. | J18: schemas/event-v0.json | K18: Evento não confirmado é distinguível de estado salvo; replay e conflitos têm regras explícitas. | L18: SL-S02-05 | M18: R02; R04; R05; R11; R13; R32; R37 | N18: Não iniciado | O18: P0 | P18: Crítico | Q18: Obrigatória no escopo da versão | R18: Autor + agente de IA | U18: reports/S02/SL-S02-06.md | X18: =IF(N18="Concluído",IF(AND(S18<>"",ISNUMBER(T18),T18>0,V18<>"",AND(OR(X17="OK",X17="DISPENSADO"))),"OK","REVISAR"),IF(N18="Dispensado (ADR)",IF(AND(LEFT(Q18,11)="Condicional",W18<>"",S18<>"",ISNUMBER(T18),T18>0,V18<>""),"DISPENSADO","REVISAR"),"PENDENTE"))
A19: 18 | B19: SL-S02-07 | C19: v0.0.1 | D19: S02 | E19: Vault / contratos | F19: Próprio | G19: Contrato | H19: Especificar evidência | I19: Combinar source_id, revisão, trecho, localizador, hash e bloco de destino. | J19: schemas/evidence-v0.json | K19: Referência distingue texto citado de comentário e não se torna inválida por renomeação. | L19: SL-S02-06 | M19: R02; R04; R05; R11; R13; R32; R37 | N19: Não iniciado | O19: P0 | P19: Crítico | Q19: Obrigatória no escopo da versão | R19: Autor + agente de IA | U19: reports/S02/SL-S02-07.md | X19: =IF(N19="Concluído",IF(AND(S19<>"",ISNUMBER(T19),T19>0,V19<>"",AND(OR(X18="OK",X18="DISPENSADO"))),"OK","REVISAR"),IF(N19="Dispensado (ADR)",IF(AND(LEFT(Q19,11)="Condicional",W19<>"",S19<>"",ISNUMBER(T19),T19>0,V19<>""),"DISPENSADO","REVISAR"),"PENDENTE"))
A20: 19 | B20: SL-S02-08 | C20: v0.0.1 | D20: S02 | E20: Vault / contratos | F20: Próprio | G20: Contrato | H20: Especificar metadados de IA | I20: Separar resumo gerado/editado, tags sugeridas/aceitas e identificação do pipeline. | J20: schemas/enrichment-v0.json | K20: Reprocessamento não sobrescreve correção humana; cobertura parcial pode ser declarada. | L20: SL-S02-07 | M20: R02; R04; R05; R11; R13; R32; R37 | N20: Não iniciado | O20: P0 | P20: Crítico | Q20: Obrigatória no escopo da versão | R20: Autor + agente de IA | U20: reports/S02/SL-S02-08.md | X20: =IF(N20="Concluído",IF(AND(S20<>"",ISNUMBER(T20),T20>0,V20<>"",AND(OR(X19="OK",X19="DISPENSADO"))),"OK","REVISAR"),IF(N20="Dispensado (ADR)",IF(AND(LEFT(Q20,11)="Condicional",W20<>"",S20<>"",ISNUMBER(T20),T20>0,V20<>""),"DISPENSADO","REVISAR"),"PENDENTE"))
A21: 20 | B21: SL-S02-09 | C21: v0.0.1 | D21: S02 | E21: Vault / contratos | F21: Próprio | G21: Teste | H21: Construir fixtures válidas e inválidas | I21: Criar um Vault mínimo, um completo e casos com campos desconhecidos. | J21: tests/fixtures/schema/ | K21: Validadores aceitam extensões permitidas e rejeitam IDs duplicados, tipos errados e referências impossíveis. | L21: SL-S02-08 | M21: R02; R04; R05; R11; R13; R32; R37 | N21: Não iniciado | O21: P0 | P21: Crítico | Q21: Obrigatória no escopo da versão | R21: Autor + agente de IA | U21: reports/S02/SL-S02-09.md | X21: =IF(N21="Concluído",IF(AND(S21<>"",ISNUMBER(T21),T21>0,V21<>"",AND(OR(X20="OK",X20="DISPENSADO"))),"OK","REVISAR"),IF(N21="Dispensado (ADR)",IF(AND(LEFT(Q21,11)="Condicional",W21<>"",S21<>"",ISNUMBER(T21),T21>0,V21<>""),"DISPENSADO","REVISAR"),"PENDENTE"))
A22: 21 | B22: SL-S02-10 | C22: v0.0.1 | D22: S02 | E22: Vault / contratos | F22: Próprio | G22: Decisão | H22: Definir evolução de schema | I22: Documentar migração, versão desconhecida, abertura somente leitura e exportação. | J22: docs/contracts/schema-evolution.md | K22: Um app antigo nunca regrava silenciosamente um formato novo que não compreende. | L22: SL-S02-09 | M22: R02; R04; R05; R11; R13; R32; R37 | N22: Não iniciado | O22: P0 | P22: Crítico | Q22: Obrigatória no escopo da versão | R22: Autor | U22: reports/S02/SL-S02-10.md | X22: =IF(N22="Concluído",IF(AND(S22<>"",ISNUMBER(T22),T22>0,V22<>"",AND(OR(X21="OK",X21="DISPENSADO"))),"OK","REVISAR"),IF(N22="Dispensado (ADR)",IF(AND(LEFT(Q22,11)="Condicional",W22<>"",S22<>"",ISNUMBER(T22),T22>0,V22<>""),"DISPENSADO","REVISAR"),"PENDENTE"))
A23: 22 | B23: SL-S02-GATE | C23: v0.0.1 | D23: S02 | E23: Vault / contratos | F23: Aceite humano | G23: Gate | H23: Aceitar S02 — Definir formatos, identidade e autoridade | I23: Revisar as dez tarefas, executar a demonstração do sprint, confrontar critérios e registrar decisão go/no-go. | J23: reports/S02/acceptance.md | K23: Fixtures independentes dos motores representam uma mesa e uma Peça completas. Todas as dependências aceitas; evidências vinculadas a revisão/ambiente; nenhum blocker de integridade/segurança. | L23: SL-S02-01; SL-S02-02; SL-S02-03; SL-S02-04; SL-S02-05; SL-S02-06; SL-S02-07; SL-S02-08; SL-S02-09; SL-S02-10 | M23: R02; R04; R05; R11; R13; R32; R37 | N23: Não iniciado | O23: P0 | P23: Crítico | Q23: Obrigatória para fechar a versão aprovada | R23: Autor | U23: reports/S02/acceptance.md | X23: =IF(N23="Concluído",IF(AND(S23<>"",ISNUMBER(T23),T23>0,V23<>"",AND(OR(X13="OK",X13="DISPENSADO"),OR(X14="OK",X14="DISPENSADO"),OR(X15="OK",X15="DISPENSADO"),OR(X16="OK",X16="DISPENSADO"),OR(X17="OK",X17="DISPENSADO"),OR(X18="OK",X18="DISPENSADO"),OR(X19="OK",X19="DISPENSADO"),OR(X20="OK",X20="DISPENSADO"),OR(X21="OK",X21="DISPENSADO"),OR(X22="OK",X22="DISPENSADO"))),"OK","REVISAR"),IF(N23="Dispensado (ADR)",IF(AND(LEFT(Q23,11)="Condicional",W23<>"",S23<>"",ISNUMBER(T23),T23>0,V23<>""),"DISPENSADO","REVISAR"),"PENDENTE"))
A24: 23 | B24: SL-S03-01 | C24: v0.0.1 | D24: S03 | E24: Todos os motores / licenças | F24: Desconstrução | G24: Upstream | H24: Inventariar repositórios | I24: Registrar URL, licença observada, linguagens, releases e componentes transitivos críticos. | J24: upstream/catalog.yaml | K24: BlockSuite, PageIndex, Docling, Jev, Qdrant, HelixDB, Scrapling, SearxNG e LocalAI estão cobertos. | L24: SL-S01-GATE; SL-S02-GATE | M24: R03; R30; R33; R34 | N24: Não iniciado | O24: P0 | P24: Crítico | Q24: Obrigatória no escopo da versão | R24: Autor + agente de IA | U24: reports/S03/SL-S03-01.md | X24: =IF(N24="Concluído",IF(AND(S24<>"",ISNUMBER(T24),T24>0,V24<>"",AND(OR(X12="OK",X12="DISPENSADO"),OR(X23="OK",X23="DISPENSADO"))),"OK","REVISAR"),IF(N24="Dispensado (ADR)",IF(AND(LEFT(Q24,11)="Condicional",W24<>"",S24<>"",ISNUMBER(T24),T24>0,V24<>""),"DISPENSADO","REVISAR"),"PENDENTE"))
A25: 24 | B25: SL-S03-02 | C25: v0.0.1 | D25: S03 | E25: Todos os motores / licenças | F25: Desconstrução | G25: Upstream | H25: Criar manifesto de origem | I25: Definir campos commit/tag, hashes, patches, avisos e comando de build. | J25: upstream/manifest.schema.json | K25: Nenhum componente empacotado pode usar latest ou branch móvel sem resolução para uma revisão. | L25: SL-S03-01 | M25: R03; R30; R33; R34 | N25: Não iniciado | O25: P0 | P25: Crítico | Q25: Obrigatória no escopo da versão | R25: Autor + agente de IA | U25: reports/S03/SL-S03-02.md | X25: =IF(N25="Concluído",IF(AND(S25<>"",ISNUMBER(T25),T25>0,V25<>"",AND(OR(X24="OK",X24="DISPENSADO"))),"OK","REVISAR"),IF(N25="Dispensado (ADR)",IF(AND(LEFT(Q25,11)="Condicional",W25<>"",S25<>"",ISNUMBER(T25),T25>0,V25<>""),"DISPENSADO","REVISAR"),"PENDENTE"))
A26: 25 | B26: SL-S03-03 | C26: v0.0.1 | D26: S03 | E26: Todos os motores / licenças | F26: Desconstrução | G26: Licença | H26: Examinar BlockSuite por árvore | I26: Distinguir standalone de AFFiNE e fechar o inventário dos arquivos candidatos. | J26: docs/legal/blocksuite-scope.md | K26: Licença não é inferida apenas pelo nome do projeto ou por um único package.json. | L26: SL-S03-02 | M26: R03; R30; R33; R34 | N26: Não iniciado | O26: P0 | P26: Crítico | Q26: Obrigatória no escopo da versão | R26: Autor | U26: reports/S03/SL-S03-03.md | X26: =IF(N26="Concluído",IF(AND(S26<>"",ISNUMBER(T26),T26>0,V26<>"",AND(OR(X25="OK",X25="DISPENSADO"))),"OK","REVISAR"),IF(N26="Dispensado (ADR)",IF(AND(LEFT(Q26,11)="Condicional",W26<>"",S26<>"",ISNUMBER(T26),T26>0,V26<>""),"DISPENSADO","REVISAR"),"PENDENTE"))
A27: 26 | B27: SL-S03-04 | C27: v0.0.1 | D27: S03 | E27: Todos os motores / licenças | F27: Desconstrução | G27: Licença | H27: Examinar SearxNG e modelos | I27: Separar código AGPL, integração por API e termos dos pesos/backends. | J27: docs/legal/component-obligations.md | K27: Fonte correspondente, avisos e redistribuição estão mapeados por artefato. | L27: SL-S03-03 | M27: R03; R30; R33; R34 | N27: Não iniciado | O27: P0 | P27: Crítico | Q27: Obrigatória no escopo da versão | R27: Autor | U27: reports/S03/SL-S03-04.md | X27: =IF(N27="Concluído",IF(AND(S27<>"",ISNUMBER(T27),T27>0,V27<>"",AND(OR(X26="OK",X26="DISPENSADO"))),"OK","REVISAR"),IF(N27="Dispensado (ADR)",IF(AND(LEFT(Q27,11)="Condicional",W27<>"",S27<>"",ISNUMBER(T27),T27>0,V27<>""),"DISPENSADO","REVISAR"),"PENDENTE"))
A28: 27 | B28: SL-S03-05 | C28: v0.0.1 | D28: S03 | E28: Todos os motores / licenças | F28: Desconstrução | G28: Decisão | H28: Ratificar licença própria | I28: Resolver ADR-003; explicar operação não comercial versus direitos open source de terceiros. | J28: docs/adr/003-license.md | K28: Licença aprovada sem cláusula non-commercial incompatível disfarçada de open source. | L28: SL-S03-04 | M28: R03; R30; R33; R34 | N28: Não iniciado | O28: P0 | P28: Crítico | Q28: Obrigatória no escopo da versão | R28: Autor | U28: reports/S03/SL-S03-05.md | X28: =IF(N28="Concluído",IF(AND(S28<>"",ISNUMBER(T28),T28>0,V28<>"",AND(OR(X27="OK",X27="DISPENSADO"))),"OK","REVISAR"),IF(N28="Dispensado (ADR)",IF(AND(LEFT(Q28,11)="Condicional",W28<>"",S28<>"",ISNUMBER(T28),T28>0,V28<>""),"DISPENSADO","REVISAR"),"PENDENTE"))
A29: 28 | B29: SL-S03-06 | C29: v0.0.1 | D29: S03 | E29: Todos os motores / licenças | F29: Desconstrução | G29: Upstream | H29: Delimitar reutilização | I29: Marcar bibliotecas, adapters, forks mínimos e serviços; excluir UIs completas e stores concorrentes. | J29: docs/architecture/reuse-map.md | K29: Cada motor tem lista de incluir/excluir e interfaces Sandland responsáveis pela autoridade. | L29: SL-S03-05 | M29: R03; R30; R33; R34 | N29: Não iniciado | O29: P0 | P29: Crítico | Q29: Obrigatória no escopo da versão | R29: Autor + agente de IA | U29: reports/S03/SL-S03-06.md | X29: =IF(N29="Concluído",IF(AND(S29<>"",ISNUMBER(T29),T29>0,V29<>"",AND(OR(X28="OK",X28="DISPENSADO"))),"OK","REVISAR"),IF(N29="Dispensado (ADR)",IF(AND(LEFT(Q29,11)="Condicional",W29<>"",S29<>"",ISNUMBER(T29),T29>0,V29<>""),"DISPENSADO","REVISAR"),"PENDENTE"))
A30: 29 | B30: SL-S03-07 | C30: v0.0.1 | D30: S03 | E30: Todos os motores / licenças | F30: Desconstrução | G30: Upstream | H30: Definir política de patches | I30: Criar série pequena e reprodutível; separar correções genéricas de customizações. | J30: upstream/PATCH_POLICY.md | K30: Um fork pode ser rebaseado e sua diferença para upstream pode ser enumerada. | L30: SL-S03-06 | M30: R03; R30; R33; R34 | N30: Não iniciado | O30: P0 | P30: Crítico | Q30: Obrigatória no escopo da versão | R30: Autor + agente de IA | U30: reports/S03/SL-S03-07.md | X30: =IF(N30="Concluído",IF(AND(S30<>"",ISNUMBER(T30),T30>0,V30<>"",AND(OR(X29="OK",X29="DISPENSADO"))),"OK","REVISAR"),IF(N30="Dispensado (ADR)",IF(AND(LEFT(Q30,11)="Condicional",W30<>"",S30<>"",ISNUMBER(T30),T30>0,V30<>""),"DISPENSADO","REVISAR"),"PENDENTE"))
A31: 30 | B31: SL-S03-08 | C31: v0.0.1 | D31: S03 | E31: Todos os motores / licenças | F31: Desconstrução | G31: Governança | H31: Preparar avisos e SBOM | I31: Criar estrutura de LICENSES, NOTICE e inventário de dependências. | J31: compliance/ | K31: Não há licença de terceiros substituída pela licença própria sem base legal. | L31: SL-S03-07 | M31: R03; R30; R33; R34 | N31: Não iniciado | O31: P0 | P31: Crítico | Q31: Obrigatória no escopo da versão | R31: Autor | U31: reports/S03/SL-S03-08.md | X31: =IF(N31="Concluído",IF(AND(S31<>"",ISNUMBER(T31),T31>0,V31<>"",AND(OR(X30="OK",X30="DISPENSADO"))),"OK","REVISAR"),IF(N31="Dispensado (ADR)",IF(AND(LEFT(Q31,11)="Condicional",W31<>"",S31<>"",ISNUMBER(T31),T31>0,V31<>""),"DISPENSADO","REVISAR"),"PENDENTE"))
A32: 31 | B32: SL-S03-09 | C32: v0.0.1 | D32: S03 | E32: Todos os motores / licenças | F32: Desconstrução | G32: Governança | H32: Definir ciclo de atualização | I32: Fixar auditoria, testes diferenciais, rollback e prioridade para vulnerabilidades. | J32: docs/maintenance/upstream.md | K32: Atualização sem evidência não chega automaticamente ao usuário ou altera modelos instalados. | L32: SL-S03-08 | M32: R03; R30; R33; R34 | N32: Não iniciado | O32: P0 | P32: Crítico | Q32: Obrigatória no escopo da versão | R32: Autor | U32: reports/S03/SL-S03-09.md | X32: =IF(N32="Concluído",IF(AND(S32<>"",ISNUMBER(T32),T32>0,V32<>"",AND(OR(X31="OK",X31="DISPENSADO"))),"OK","REVISAR"),IF(N32="Dispensado (ADR)",IF(AND(LEFT(Q32,11)="Condicional",W32<>"",S32<>"",ISNUMBER(T32),T32>0,V32<>""),"DISPENSADO","REVISAR"),"PENDENTE"))
A33: 32 | B33: SL-S03-10 | C33: v0.0.1 | D33: S03 | E33: Todos os motores / licenças | F33: Desconstrução | G33: Decisão | H33: Definir limites de spikes | I33: Para cada prova, listar pergunta, corpus, evidência mínima e decisão de continuar/replanejar. | J33: docs/spikes/register.md | K33: Relatório inconclusivo não vira integração aprovada; Qdrant e Helix têm protocolo comparável. | L33: SL-S03-09 | M33: R03; R30; R33; R34 | N33: Não iniciado | O33: P0 | P33: Crítico | Q33: Obrigatória no escopo da versão | R33: Autor | U33: reports/S03/SL-S03-10.md | X33: =IF(N33="Concluído",IF(AND(S33<>"",ISNUMBER(T33),T33>0,V33<>"",AND(OR(X32="OK",X32="DISPENSADO"))),"OK","REVISAR"),IF(N33="Dispensado (ADR)",IF(AND(LEFT(Q33,11)="Condicional",W33<>"",S33<>"",ISNUMBER(T33),T33>0,V33<>""),"DISPENSADO","REVISAR"),"PENDENTE"))
A34: 33 | B34: SL-S03-GATE | C34: v0.0.1 | D34: S03 | E34: Todos os motores / licenças | F34: Aceite humano | G34: Gate | H34: Aceitar S03 — Inventariar upstreams e definir recortes | I34: Revisar as dez tarefas, executar a demonstração do sprint, confrontar critérios e registrar decisão go/no-go. | J34: reports/S03/acceptance.md | K34: Cada motor tem origem rastreável, fronteira proposta e decisão de manter/extrair/adaptar. Todas as dependências aceitas; evidências vinculadas a revisão/ambiente; nenhum blocker de integridade/segurança. | L34: SL-S03-01; SL-S03-02; SL-S03-03; SL-S03-04; SL-S03-05; SL-S03-06; SL-S03-07; SL-S03-08; SL-S03-09; SL-S03-10 | M34: R03; R30; R33; R34 | N34: Não iniciado | O34: P0 | P34: Crítico | Q34: Obrigatória para fechar a versão aprovada | R34: Autor | U34: reports/S03/acceptance.md | X34: =IF(N34="Concluído",IF(AND(S34<>"",ISNUMBER(T34),T34>0,V34<>"",AND(OR(X24="OK",X24="DISPENSADO"),OR(X25="OK",X25="DISPENSADO"),OR(X26="OK",X26="DISPENSADO"),OR(X27="OK",X27="DISPENSADO"),OR(X28="OK",X28="DISPENSADO"),OR(X29="OK",X29="DISPENSADO"),OR(X30="OK",X30="DISPENSADO"),OR(X31="OK",X31="DISPENSADO"),OR(X32="OK",X32="DISPENSADO"),OR(X33="OK",X33="DISPENSADO"))),"OK","REVISAR"),IF(N34="Dispensado (ADR)",IF(AND(LEFT(Q34,11)="Condicional",W34<>"",S34<>"",ISNUMBER(T34),T34>0,V34<>""),"DISPENSADO","REVISAR"),"PENDENTE"))
A35: 34 | B35: SL-S04-01 | C35: v0.0.2 | D35: S04 | E35: Ferramentas / governança | F35: Próprio | G35: Implementação | H35: Criar estrutura do monorepo | I35: Separar app desktop, crates, adapters, workers, schemas, fixtures e docs. | J35: repository-layout.md | K35: Dependências apontam para contratos e não para UI/estado privado de outro motor. | L35: SL-S03-GATE | M35: R03; R30; R33; R34 | N35: Não iniciado | O35: P0 | P35: Crítico | Q35: Obrigatória no escopo da versão | R35: Autor + agente de IA | U35: reports/S04/SL-S04-01.md | X35: =IF(N35="Concluído",IF(AND(S35<>"",ISNUMBER(T35),T35>0,V35<>"",AND(OR(X34="OK",X34="DISPENSADO"))),"OK","REVISAR"),IF(N35="Dispensado (ADR)",IF(AND(LEFT(Q35,11)="Condicional",W35<>"",S35<>"",ISNUMBER(T35),T35>0,V35<>""),"DISPENSADO","REVISAR"),"PENDENTE"))
A36: 35 | B36: SL-S04-02 | C36: v0.0.2 | D36: S04 | E36: Ferramentas / governança | F36: Próprio | G36: Implementação | H36: Fixar toolchains | I36: Pin Rust, JS e runtimes necessários para desenvolvimento, sem instaladores globais implícitos. | J36: toolchains.lock | K36: Ambiente limpo reproduz versões; mudanças de versão são diff explícito. | L36: SL-S04-01 | M36: R03; R30; R33; R34 | N36: Não iniciado | O36: P0 | P36: Crítico | Q36: Obrigatória no escopo da versão | R36: Autor + agente de IA | U36: reports/S04/SL-S04-02.md | X36: =IF(N36="Concluído",IF(AND(S36<>"",ISNUMBER(T36),T36>0,V36<>"",AND(OR(X35="OK",X35="DISPENSADO"))),"OK","REVISAR"),IF(N36="Dispensado (ADR)",IF(AND(LEFT(Q36,11)="Condicional",W36<>"",S36<>"",ISNUMBER(T36),T36>0,V36<>""),"DISPENSADO","REVISAR"),"PENDENTE"))
A37: 36 | B37: SL-S04-03 | C37: v0.0.2 | D37: S04 | E37: Ferramentas / governança | F37: Próprio | G37: Implementação | H37: Configurar formatadores e lint | I37: Definir regras por linguagem e exclusões de fontes vendorizadas. | J37: tooling/lint/ | K37: Comando único reporta erros sem reformatar ou apagar avisos de arquivos upstream. | L37: SL-S04-02 | M37: R03; R30; R33; R34 | N37: Não iniciado | O37: P0 | P37: Crítico | Q37: Obrigatória no escopo da versão | R37: Autor + agente de IA | U37: reports/S04/SL-S04-03.md | X37: =IF(N37="Concluído",IF(AND(S37<>"",ISNUMBER(T37),T37>0,V37<>"",AND(OR(X36="OK",X36="DISPENSADO"))),"OK","REVISAR"),IF(N37="Dispensado (ADR)",IF(AND(LEFT(Q37,11)="Condicional",W37<>"",S37<>"",ISNUMBER(T37),T37>0,V37<>""),"DISPENSADO","REVISAR"),"PENDENTE"))
A38: 37 | B38: SL-S04-04 | C38: v0.0.2 | D38: S04 | E38: Ferramentas / governança | F38: Próprio | G38: Implementação | H38: Criar comandos de projeto | I38: Padronizar bootstrap, check, test, fixtures e pacote de evidências. | J38: tooling/tasks/ | K38: Comandos têm help, retorno de erro confiável e não dependem do histórico do shell. | L38: SL-S04-03 | M38: R03; R30; R33; R34 | N38: Não iniciado | O38: P0 | P38: Crítico | Q38: Obrigatória no escopo da versão | R38: Autor + agente de IA | U38: reports/S04/SL-S04-04.md | X38: =IF(N38="Concluído",IF(AND(S38<>"",ISNUMBER(T38),T38>0,V38<>"",AND(OR(X37="OK",X37="DISPENSADO"))),"OK","REVISAR"),IF(N38="Dispensado (ADR)",IF(AND(LEFT(Q38,11)="Condicional",W38<>"",S38<>"",ISNUMBER(T38),T38>0,V38<>""),"DISPENSADO","REVISAR"),"PENDENTE"))
A39: 38 | B39: SL-S04-05 | C39: v0.0.2 | D39: S04 | E39: Ferramentas / governança | F39: Próprio | G39: Governança | H39: Criar política de branches | I39: Uma frente mutável principal; PRs pequenos com IDs de tarefa e rollback. | J39: CONTRIBUTING.md | K39: Dois agentes não alteram contratos compartilhados em paralelo sem acordo explícito. | L39: SL-S04-04 | M39: R03; R30; R33; R34 | N39: Não iniciado | O39: P0 | P39: Crítico | Q39: Obrigatória no escopo da versão | R39: Autor | U39: reports/S04/SL-S04-05.md | X39: =IF(N39="Concluído",IF(AND(S39<>"",ISNUMBER(T39),T39>0,V39<>"",AND(OR(X38="OK",X38="DISPENSADO"))),"OK","REVISAR"),IF(N39="Dispensado (ADR)",IF(AND(LEFT(Q39,11)="Condicional",W39<>"",S39<>"",ISNUMBER(T39),T39>0,V39<>""),"DISPENSADO","REVISAR"),"PENDENTE"))
A40: 39 | B40: SL-S04-06 | C40: v0.0.2 | D40: S04 | E40: Ferramentas / governança | F40: Próprio | G40: Governança | H40: Escrever instruções de agentes | I40: Delimitar arquivos, segredos, rede, testes obrigatórios e critérios de parada. | J40: AGENTS.md | K40: Agente não pode declarar testes executados sem logs nem aprovar a própria entrega. | L40: SL-S04-05 | M40: R03; R30; R33; R34 | N40: Não iniciado | O40: P0 | P40: Crítico | Q40: Obrigatória no escopo da versão | R40: Autor | U40: reports/S04/SL-S04-06.md | X40: =IF(N40="Concluído",IF(AND(S40<>"",ISNUMBER(T40),T40>0,V40<>"",AND(OR(X39="OK",X39="DISPENSADO"))),"OK","REVISAR"),IF(N40="Dispensado (ADR)",IF(AND(LEFT(Q40,11)="Condicional",W40<>"",S40<>"",ISNUMBER(T40),T40>0,V40<>""),"DISPENSADO","REVISAR"),"PENDENTE"))
...

Sheet Versões
A1: Versão | B1: Nome | C1: Maturidade | D1: Sprints | E1: Nº sprints | F1: Tarefas | G1: Gates | H1: Entregável diferente | I1: Tarefas aceitas | J1: Gates aceitos | K1: Tarefas dispensadas | L1: Progresso aplicável
A2: v0.0.1 | B2: Arquitetura executável | C2: Interna | D2: S01–S03 | E2: 3 | F2: 30 | G2: 3 | H2: Decisões, contratos de dados e inventário de origem aprovados; nenhuma funcionalidade de produto prometida. | I2: =COUNTIFS(Tarefas!$C$2:$C$793,A2,Tarefas!$G$2:$G$793,"<>Gate",Tarefas!$X$2:$X$793,"OK") | J2: =COUNTIFS(Tarefas!$C$2:$C$793,A2,Tarefas!$G$2:$G$793,"Gate",Tarefas!$X$2:$X$793,"OK") | K2: =COUNTIFS(Tarefas!$C$2:$C$793,A2,Tarefas!$G$2:$G$793,"<>Gate",Tarefas!$X$2:$X$793,"DISPENSADO") | L2: =IFERROR(I2/(F2-K2),0)
A3: v0.0.2 | B3: Bancada reproduzível | C3: Interna | D3: S04–S06 | E3: 3 | F3: 30 | G3: 3 | H3: Repositório, CI, fixtures e shell desktop compiláveis sem importar aplicações completas. | I3: =COUNTIFS(Tarefas!$C$2:$C$793,A3,Tarefas!$G$2:$G$793,"<>Gate",Tarefas!$X$2:$X$793,"OK") | J3: =COUNTIFS(Tarefas!$C$2:$C$793,A3,Tarefas!$G$2:$G$793,"Gate",Tarefas!$X$2:$X$793,"OK") | K3: =COUNTIFS(Tarefas!$C$2:$C$793,A3,Tarefas!$G$2:$G$793,"<>Gate",Tarefas!$X$2:$X$793,"DISPENSADO") | L3: =IFERROR(I3/(F3-K3),0)
A4: v0.1.0 | B4: Vault recuperável | C4: Alpha técnica | D4: S07–S11 | E4: 5 | F4: 50 | G4: 5 | H4: Criar, alterar, recuperar e reconstruir conhecimento local com ferramenta de diagnóstico. | I4: =COUNTIFS(Tarefas!$C$2:$C$793,A4,Tarefas!$G$2:$G$793,"<>Gate",Tarefas!$X$2:$X$793,"OK") | J4: =COUNTIFS(Tarefas!$C$2:$C$793,A4,Tarefas!$G$2:$G$793,"Gate",Tarefas!$X$2:$X$793,"OK") | K4: =COUNTIFS(Tarefas!$C$2:$C$793,A4,Tarefas!$G$2:$G$793,"<>Gate",Tarefas!$X$2:$X$793,"DISPENSADO") | L4: =IFERROR(I4/(F4-K4),0)
A5: v0.2.0 | B5: Editor local BlockSuite | C5: Alpha de autoria | D5: S12–S15 | E5: 4 | F5: 40 | G5: 4 | H5: Editar notas no perfil Markdown suportado e reabrir sem depender do estado interno do editor. | I5: =COUNTIFS(Tarefas!$C$2:$C$793,A5,Tarefas!$G$2:$G$793,"<>Gate",Tarefas!$X$2:$X$793,"OK") | J5: =COUNTIFS(Tarefas!$C$2:$C$793,A5,Tarefas!$G$2:$G$793,"Gate",Tarefas!$X$2:$X$793,"OK") | K5: =COUNTIFS(Tarefas!$C$2:$C$793,A5,Tarefas!$G$2:$G$793,"<>Gate",Tarefas!$X$2:$X$793,"DISPENSADO") | L5: =IFERROR(I5/(F5-K5),0)
A6: v0.3.0 | B6: Mesa espacial | C6: Alpha de autoria | D6: S16–S19 | E6: 4 | F6: 40 | G6: 4 | H6: Organizar células, grupos e relações com PixiJS e edição BlockSuite integrada. | I6: =COUNTIFS(Tarefas!$C$2:$C$793,A6,Tarefas!$G$2:$G$793,"<>Gate",Tarefas!$X$2:$X$793,"OK") | J6: =COUNTIFS(Tarefas!$C$2:$C$793,A6,Tarefas!$G$2:$G$793,"Gate",Tarefas!$X$2:$X$793,"OK") | K6: =COUNTIFS(Tarefas!$C$2:$C$793,A6,Tarefas!$G$2:$G$793,"<>Gate",Tarefas!$X$2:$X$793,"DISPENSADO") | L6: =IFERROR(I6/(F6-K6),0)
A7: v0.4.0 | B7: Peça e proveniência | C7: Alpha funcional sem IA | D7: S20–S22 | E7: 3 | F7: 30 | G7: 3 | H7: Produzir texto editorial a partir da Mesa com fork-on-insert, referências e exportação. | I7: =COUNTIFS(Tarefas!$C$2:$C$793,A7,Tarefas!$G$2:$G$793,"<>Gate",Tarefas!$X$2:$X$793,"OK") | J7: =COUNTIFS(Tarefas!$C$2:$C$793,A7,Tarefas!$G$2:$G$793,"Gate",Tarefas!$X$2:$X$793,"OK") | K7: =COUNTIFS(Tarefas!$C$2:$C$793,A7,Tarefas!$G$2:$G$793,"<>Gate",Tarefas!$X$2:$X$793,"DISPENSADO") | L7: =IFERROR(I7/(F7-K7),0)
A8: v0.5.0 | B8: Ingestão segura | C8: Alpha de acervo | D8: S23–S30 | E8: 8 | F8: 80 | G8: 8 | H8: Capturar arquivos/HTML, extrair texto e OCR em workers confinados e organizar o acervo. | I8: =COUNTIFS(Tarefas!$C$2:$C$793,A8,Tarefas!$G$2:$G$793,"<>Gate",Tarefas!$X$2:$X$793,"OK") | J8: =COUNTIFS(Tarefas!$C$2:$C$793,A8,Tarefas!$G$2:$G$793,"Gate",Tarefas!$X$2:$X$793,"OK") | K8: =COUNTIFS(Tarefas!$C$2:$C$793,A8,Tarefas!$G$2:$G$793,"<>Gate",Tarefas!$X$2:$X$793,"DISPENSADO") | L8: =IFERROR(I8/(F8-K8),0)
A9: v0.6.0 | B9: Enriquecimento e modelos | C9: Alpha assistida | D9: S31–S36 | E9: 6 | F9: 60 | G9: 6 | H9: LocalAI gerenciado, resumos, Jev autorizado, fallback local e transcrição homologada. | I9: =COUNTIFS(Tarefas!$C$2:$C$793,A9,Tarefas!$G$2:$G$793,"<>Gate",Tarefas!$X$2:$X$793,"OK") | J9: =COUNTIFS(Tarefas!$C$2:$C$793,A9,Tarefas!$G$2:$G$793,"Gate",Tarefas!$X$2:$X$793,"OK") | K9: =COUNTIFS(Tarefas!$C$2:$C$793,A9,Tarefas!$G$2:$G$793,"<>Gate",Tarefas!$X$2:$X$793,"DISPENSADO") | L9: =IFERROR(I9/(F9-K9),0)
A10: v0.7.0 | B10: Busca híbrida | C10: Alpha integrada | D10: S37–S41 | E10: 5 | F10: 50 | G10: 5 | H10: Escolher Qdrant OU HelixDB e recuperar materiais/Peças com índices descartáveis e revisões válidas. | I10: =COUNTIFS(Tarefas!$C$2:$C$793,A10,Tarefas!$G$2:$G$793,"<>Gate",Tarefas!$X$2:$X$793,"OK") | J10: =COUNTIFS(Tarefas!$C$2:$C$793,A10,Tarefas!$G$2:$G$793,"Gate",Tarefas!$X$2:$X$793,"OK") | K10: =COUNTIFS(Tarefas!$C$2:$C$793,A10,Tarefas!$G$2:$G$793,"<>Gate",Tarefas!$X$2:$X$793,"DISPENSADO") | L10: =IFERROR(I10/(F10-K10),0)
A11: v0.8.0 | B11: Contexto estrutural | C11: Alpha de raciocínio | D11: S42–S46 | E11: 5 | F11: 50 | G11: 5 | H11: PageIndex adaptado às células, Skeleton Map e recuperação relacional limitada por escopo e orçamento. | I11: =COUNTIFS(Tarefas!$C$2:$C$793,A11,Tarefas!$G$2:$G$793,"<>Gate",Tarefas!$X$2:$X$793,"OK") | J11: =COUNTIFS(Tarefas!$C$2:$C$793,A11,Tarefas!$G$2:$G$793,"Gate",Tarefas!$X$2:$X$793,"OK") | K11: =COUNTIFS(Tarefas!$C$2:$C$793,A11,Tarefas!$G$2:$G$793,"<>Gate",Tarefas!$X$2:$X$793,"DISPENSADO") | L11: =IFERROR(I11/(F11-K11),0)
A12: v0.9.0 | B12: Ciclo analítico completo | C12: Alpha de ciclo completo | D12: S47–S53 | E12: 7 | F12: 70 | G12: 7 | H12: Pesquisa web, widget, copiloto, chat e intenções conectam Captura → Mesa → Peça. | I12: =COUNTIFS(Tarefas!$C$2:$C$793,A12,Tarefas!$G$2:$G$793,"<>Gate",Tarefas!$X$2:$X$793,"OK") | J12: =COUNTIFS(Tarefas!$C$2:$C$793,A12,Tarefas!$G$2:$G$793,"Gate",Tarefas!$X$2:$X$793,"OK") | K12: =COUNTIFS(Tarefas!$C$2:$C$793,A12,Tarefas!$G$2:$G$793,"<>Gate",Tarefas!$X$2:$X$793,"DISPENSADO") | L12: =IFERROR(I12/(F12-K12),0)
A13: v1.0.0-beta.1 | B13: Homologação multiplataforma | C13: Beta | D13: S54–S57 | E13: 4 | F13: 40 | G13: 4 | H13: Segurança, performance e pacotes validados nos cinco alvos, sem presumir paridade de aceleração. | I13: =COUNTIFS(Tarefas!$C$2:$C$793,A13,Tarefas!$G$2:$G$793,"<>Gate",Tarefas!$X$2:$X$793,"OK") | J13: =COUNTIFS(Tarefas!$C$2:$C$793,A13,Tarefas!$G$2:$G$793,"Gate",Tarefas!$X$2:$X$793,"OK") | K13: =COUNTIFS(Tarefas!$C$2:$C$793,A13,Tarefas!$G$2:$G$793,"<>Gate",Tarefas!$X$2:$X$793,"DISPENSADO") | L13: =IFERROR(I13/(F13-K13),0)
... A20: v2.0.0 | B20: Plataforma estável e sustentável | C20: Estável — fim do horizonte | D20: S72–S72 | E20: 1 | F20: 10 | G20: 1 | H20: Base madura, interoperável e extensível; continuidade de manutenção, não fim definitivo do projeto. | I20: =COUNTIFS(Tarefas!$C$2:$C$793,A20,Tarefas!$G$2:$G$793,"<>Gate",Tarefas!$X$2:$X$793,"OK") | J20: =COUNTIFS(Tarefas!$C$2:$C$793,A20,Tarefas!$G$2:$G$793,"Gate",Tarefas!$X$2:$X$793,"OK") | K20: =COUNTIFS(Tarefas!$C$2:$C$793,A20,Tarefas!$G$2:$G$793,"<>Gate",Tarefas!$X$2:$X$793,"DISPENSADO") | L20: =IFERROR(I20/(F20-K20),0)

Sheet Sprints
A1: Sprint | B1: Versão | C1: Objetivo curto | D1: Objetivo verificável | E1: Componente | F1: Forma | G1: Pré-requisitos técnicos | H1: Requisitos | I1: Entrega | J1: Demonstração de aceite | K1: Gate | L1: Risco | M1: Observação | N1: Tarefas aceitas | O1: Total tarefas | P1: Dispensadas válidas | Q1: Progresso aplicável
A2: S01 | B2: v0.0.1 | C2: Ratificar escopo, soberania e composição | D2: Eliminar decisões contraditórias antes de criar dependências de implementação. | E2: Arquitetura / produto | F2: Próprio | H2: R01; R03; R07; R08; R33; R34 | I2: Escopo v1.0 e registro de decisões iniciais. | J2: Autor consegue explicar offline, Jev, workers e cinco alvos sem contradições. | K2: SL-S01-GATE | L2: Crítico | N2: =COUNTIFS(Tarefas!$D$2:$D$793,A2,Tarefas!$G$2:$G$793,"<>Gate",Tarefas!$X$2:$X$793,"OK") | O2: 10 | P2: =COUNTIFS(Tarefas!$D$2:$D$793,A2,Tarefas!$G$2:$G$793,"<>Gate",Tarefas!$X$2:$X$793,"DISPENSADO") | Q2: =IFERROR(N2/(O2-P2),0)
A3: S02 | B3: v0.0.1 | C3: Definir formatos, identidade e autoridade | D3: Especificar representação persistente antes do editor e dos índices. | E3: Vault / contratos | F3: Próprio | G3: S01 | H3: R02; R04; R05; R11; R13; R32; R37 | I3: Schemas v0 do Vault, board, eventos, células e evidências. | J3: Fixtures independentes dos motores representam uma mesa e uma Peça completas. | K3: SL-S02-GATE | L3: Crítico | N3: =COUNTIFS(Tarefas!$D$2:$D$793,A3,Tarefas!$G$2:$G$793,"<>Gate",Tarefas!$X$2:$X$793,"OK") | O3: 10 | P3: =COUNTIFS(Tarefas!$D$2:$D$793,A3,Tarefas!$G$2:$G$793,"<>Gate",Tarefas!$X$2:$X$793,"DISPENSADO") | Q3: =IFERROR(N3/(O3-P3),0)
A4: S03 | B4: v0.0.1 | C4: Inventariar upstreams e definir recortes | D4: Fixar origem, licenças e modo de integração sem criar forks indiscriminados. | E4: Todos os motores / licenças | F4: Desconstrução | G4: S01; S02 | H4: R03; R30; R33; R34 | I4: Catálogo de componentes e política de manutenção upstream. | J4: Cada motor tem origem rastreável, fronteira proposta e decisão de manter/extrair/adaptar. | K4: SL-S03-GATE | L4: Crítico | N4: =COUNTIFS(Tarefas!$D$2:$D$793,A4,Tarefas!$G$2:$G$793,"<>Gate",Tarefas!$X$2:$X$793,"OK") | O4: 10 | P4: =COUNTIFS(Tarefas!$D$2:$D$793,A4,Tarefas!$G$2:$G$793,"<>Gate",Tarefas!$X$2:$X$793,"DISPENSADO") | Q4: =IFERROR(N4/(O4-P4),0)
A5: S04 | B5: v0.0.2 | C5: Montar repositório e fluxo solo com IA | D5: Tornar alterações pequenas, revisáveis e reproduzíveis por um único mantenedor. | E5: Ferramentas / governança | F5: Próprio | G5: S03 | H5: R03; R30; R33; R34 | I5: Monorepo de trabalho e instruções de contribuição/agentes. | J5: Um agente implementa uma tarefa isolada e o autor consegue revisar o patch e seus testes. | K5: SL-S04-GATE | L5: Crítico | N5: =COUNTIFS(Tarefas!$D$2:$D$793,A5,Tarefas!$G$2:$G$793,"<>Gate",Tarefas!$X$2:$X$793,"OK") | O5: 10 | P5: =COUNTIFS(Tarefas!$D$2:$D$793,A5,Tarefas!$G$2:$G$793,"<>Gate",Tarefas!$X$2:$X$793,"DISPENSADO") | Q5: =IFERROR(N5/(O5-P5),0)
A6: S05 | B6: v0.0.2 | C6: Construir CI, corpus e protocolo de medição | D6: Criar a bancada que impedirá promessas de qualidade ou recursos sem medição. | E6: Qualidade / desempenho | F6: Próprio | G6: S04 | H6: R01; R09; R12; R15; R20; R34 | I6: CI inicial, corpus licenciado e perfis mensuráveis. | J6: Falha introduzida em contrato bloqueia pipeline e um benchmark gera dados reproduzíveis. | K6: SL-S05-GATE | L6: Alto | N6: =COUNTIFS(Tarefas!$D$2:$D$793,A6,Tarefas!$G$2:$G$793,"<>Gate",Tarefas!$X$2:$X$793,"OK") | O6: 10 | P6: =COUNTIFS(Tarefas!$D$2:$D$793,A6,Tarefas!$G$2:$G$793,"<>Gate",Tarefas!$X$2:$X$793,"DISPENSADO") | Q6: =IFERROR(N6/(O6-P6),0)
A7: S06 | B7: v0.0.2 | C7: Criar shell desktop e contratos IPC | D7: Abrir um app local mínimo sem antecipar a integração de todos os motores. | E7: Tauri / apresentação | F7: Integração | G7: S04; S05 | H7: R01; R03; R07; R08; R31; R34 | I7: Shell Tauri com navegação Ingest/Mesa/Peça e IPC validado. | J7: Instalar build de desenvolvimento, navegar e selecionar um diretório sem rede. | K7: SL-S06-GATE | L7: Crítico | N7: =COUNTIFS(Tarefas!$D$2:$D$793,A7,Tarefas!$G$2:$G$793,"<>Gate",Tarefas!$X$2:$X$793,"OK") | O7: 10 | P7: =COUNTIFS(Tarefas!$D$2:$D$793,A7,Tarefas!$G$2:$G$793,"<>Gate",Tarefas!$X$2:$X$793,"DISPENSADO") | Q7: =IFERROR(N7/(O7-P7),0)
A8: S07 | B8: v0.1.0 | C8: Implementar Vault, identidade e assets | D8: Criar a primeira autoridade persistente do produto. | E8: VaultStore / CAS | F8: Próprio | G8: S02; S06 | H8: R02; R04; R05; R07 | I8: VaultStore básico, manifest e armazenamento de assets por hash. | J8: Criar Vault, salvar nota/asset, fechar e listar os mesmos IDs ao reabrir. | K8: SL-S07-GATE | L8: Crítico | N8: =COUNTIFS(Tarefas!$D$2:$D$793,A8,Tarefas!$G$2:$G$793,"<>Gate",Tarefas!$X$2:$X$793,"OK") | O8: 10 | P8: =COUNTIFS(Tarefas!$D$2:$D$793,A8,Tarefas!$G$2:$G$793,"<>Gate",Tarefas!$X$2:$X$793,"DISPENSADO") | Q8: =IFERROR(N8/(O8-P8),0)
A9: S08 | B9: v0.1.0 | C9: Implementar transações de arquivos e histórico | D9: Tornar confirmação, replay e desfazer independentes de bancos descartáveis. | E9: Journal / RevisionStore | F9: Próprio | G9: S07 | H9: R02; R05; R13; R37 | I9: Journal durável e protocolo de publicação de revisões. | J9: Interromper cada etapa de uma edição e recuperar o último estado confirmado. | K9: SL-S08-GATE | L9: Crítico | N9: =COUNTIFS(Tarefas!$D$2:$D$793,A9,Tarefas!$G$2:$G$793,"<>Gate",Tarefas!$X$2:$X$793,"OK") | O9: 10 | P9: =COUNTIFS(Tarefas!$D$2:$D$793,A9,Tarefas!$G$2:$G$793,"<>Gate",Tarefas!$X$2:$X$793,"DISPENSADO") | Q9: =IFERROR(N9/(O9-P9),0)
A10: S09 | B10: v0.1.0 | C10: Implementar broker de arquivos e defesa TOCTOU | D10: Eliminar validação de path separada da abertura antes de integrar workers. | E10: VaultGuard / ToolBroker | F10: Próprio | G10: S07; S08 | H10: R06; R08; R34 | I10: I/O autorizado por referências/handles e suíte de ataques de paths. | J10: Solicitar um arquivo permitido e negar escapes durante resolução e concorrência. | K10: SL-S09-GATE | L10: Crítico | N10: =COUNTIFS(Tarefas!$D$2:$D$793,A10,Tarefas!$G$2:$G$793,"<>Gate",Tarefas!$X$2:$X$793,"OK") | O10: 10 | P10: =COUNTIFS(Tarefas!$D$2:$D$793,A10,Tarefas!$G$2:$G$793,"<>Gate",Tarefas!$X$2:$X$793,"DISPENSADO") | Q10: =IFERROR(N10/(O10-P10),0)
A11: S10 | B11: v0.1.0 | C11: Reconciliar alterações externas e reconstruir índices | D11: Manter o disco como autoridade mesmo com edição externa e perda de notificações. | E11: Watcher / projeções | F11: Próprio | G11: S08; S09 | H11: R02; R04; R05; R21 | I11: Reconciliação incremental e cache de inventário descartável. | J11: Editar/renomear fora do app, perder um evento de watcher e reconciliar sem perda. | K11: SL-S10-GATE | L11: Crítico | N11: =COUNTIFS(Tarefas!$D$2:$D$793,A11,Tarefas!$G$2:$G$793,"<>Gate",Tarefas!$X$2:$X$793,"OK") | O11: 10 | P11: =COUNTIFS(Tarefas!$D$2:$D$793,A11,Tarefas!$G$2:$G$793,"<>Gate",Tarefas!$X$2:$X$793,"DISPENSADO") | Q11: =IFERROR(N11/(O11-P11),0)
A12: S11 | B12: v0.1.0 | C12: Concluir v0.1: recuperação e diagnóstico do Vault | D12: Entregar um núcleo de dados utilizável antes de adicionar complexidade visual. | E12: Vault / integração | F12: Próprio | G12: S07; S08; S09; S10 | H12: R02; R05; R06; R07; R29; R34 | I12: v0.1.0 alpha técnica e utilitário de recuperação. | J12: Criar, modificar, corromper um cache, reconstruir e exportar um Vault local. | K12: SL-S11-GATE | L12: Crítico | N12: =COUNTIFS(Tarefas!$D$2:$D$793,A12,Tarefas!$G$2:$G$793,"<>Gate",Tarefas!$X$2:$X$793,"OK") | O12: 10 | P12: =COUNTIFS(Tarefas!$D$2:$D$793,A12,Tarefas!$G$2:$G$793,"<>Gate",Tarefas!$X$2:$X$793,"DISPENSADO") | Q12: =IFERROR(N12/(O12-P12),0)
A13: S12 | B13: v0.2.0 | C13: Extrair o recorte editorial do BlockSuite | D13: Reproduzir a edição mínima sem importar o produto AFFiNE. | E13: BlockSuite / upstream | F13: Desconstrução | G13: S03; S04; S06; S11 | H13: R03; R10; R30; R33; R34 | I13: Pacote editorial isolado e ADR do recorte. | J13: Editor mínimo funciona fora do monorepo de origem e sua origem/licença é rastreável. | K13: SL-S12-GATE | L13: Crítico | N13: =COUNTIFS(Tarefas!$D$2:$D$793,A13,Tarefas!$G$2:$G$793,"<>Gate",Tarefas!$X$2:$X$793,"OK") | O13: 10 | P13: =COUNTIFS(Tarefas!$D$2:$D$793,A13,Tarefas!$G$2:$G$793,"<>Gate",Tarefas!$X$2:$X$793,"DISPENSADO") | Q13: =IFERROR(N13/(O13-P13),0)
A14: S13 | B14: v0.2.0 | C14: Implementar ponte Markdown ↔ BlockSuite | D14: Conectar o modelo editorial ao formato autoral sem perda silenciosa. | E14: EditorBridge / formato | F14: Adaptação | G14: S02; S12 | H14: R02; R04; R10; R13; R32 | I14: Serializer/deserializer e fixtures de round-trip. | J14: Abrir Markdown externo, editar no BlockSuite e preservar a semântica e metadados. | K14: SL-S13-GATE | L14: Alto | N14: =COUNTIFS(Tarefas!$D$2:$D$793,A14,Tarefas!$G$2:$G$793,"<>Gate",Tarefas!$X$2:$X$793,"OK") | O14: 10 | P14: =COUNTIFS(Tarefas!$D$2:$D$793,A14,Tarefas!$G$2:$G$793,"<>Gate",Tarefas!$X$2:$X$793,"DISPENSADO") | Q14: =IFERROR(N14/(O14-P14),0)
... A38: S37 | B38: v0.7.0 | C38: Definir contrato e bancada de busca híbrida | D38: Comparar motores sob o mesmo contrato antes de escolhê-los. | E38: SearchService / avaliação | F38: Próprio | G38: S05; S10; S22; S32; S36 | H38: R02; R20; R21; R34 | I38: Contrato de busca, indexação e protocolo comparativo. | J38: Mesma fixture/consulta roda em providers fake e produz ranking/evidências verificáveis. | K38: SL-S37-GATE | L38: Médio | N38: =COUNTIFS(Tarefas!$D$2:$D$793,A38,Tarefas!$G$2:$G$793,"<>Gate",Tarefas!$X$2:$X$793,"OK") | O38: 10 | P38: =COUNTIFS(Tarefas!$D$2:$D$793,A38,Tarefas!$G$2:$G$793,"<>Gate",Tarefas!$X$2:$X$793,"DISPENSADO") | Q38: =IFERROR(N38/(O38-P38),0)
A39: S38 | B39: v0.7.0 | C39: Avaliar Qdrant sem incorporar servidor completo | D39: Testar Edge/Server adequados ao desktop com recorte experimental descartável. | E39: Qdrant / candidato A | F39: Spike de motor | G39: S37 | H39: R01; R20; R21; R30; R33 | I39: Relatório Qdrant e provider experimental. | J39: Executar conformidade e benchmarks iguais ao candidato B, com conclusão viável/inviável. | K39: SL-S38-GATE | L39: Crítico | M39: Este sprint fecha uma investigação, não aprova automaticamente Qdrant para produção. Conclusão negativa fundamentada é uma saída válida do spike. | N39: =COUNTIFS(Tarefas!$D$2:$D$793,A39,Tarefas!$G$2:$G$793,"<>Gate",Tarefas!$X$2:$X$793,"OK") | O39: 10 | P39: =COUNTIFS(Tarefas!$D$2:$D$793,A39,Tarefas!$G$2:$G$793,"<>Gate",Tarefas!$X$2:$X$793,"DISPENSADO") | Q39: =IFERROR(N39/(O39-P39),0)
A40: S39 | B40: v0.7.0 | C40: Avaliar HelixDB sob o mesmo contrato | D40: Medir integração embutida e busca/grafo sem tornar HelixDB fonte da verdade. | E40: HelixDB / candidato B | F40: Spike de motor | G40: S37 | H40: R01; R20; R21; R30; R33 | I40: Relatório HelixDB e provider experimental. | J40: Rodar o mesmo corpus e confrontar resultados com o candidato A. | K40: SL-S39-GATE | L40: Crítico | M40: Concluir o spike não implica adotar HelixDB. Os dois protótipos ficam em experiments e não são distribuídos juntos por padrão. | N40: =COUNTIFS(Tarefas!$D$2:$D$793,A40,Tarefas!$G$2:$G$793,"<>Gate",Tarefas!$X$2:$X$793,"OK") | O40: 10 | P40: =COUNTIFS(Tarefas!$D$2:$D$793,A40,Tarefas!$G$2:$G$793,"<>Gate",Tarefas!$X$2:$X$793,"DISPENSADO") | Q40: =IFERROR(N40/(O40-P40),0)
A41: S40 | B41: v0.7.0 | C41: Escolher e integrar um backend de busca | D41: Converter evidência comparativa em uma implementação de produto, não em dual-stack. | E41: Qdrant OU HelixDB / produção | F41: Integração | G41: S38; S39 | H41: R02; R20; R21; R30; R32 | I41: SearchProvider de produção e ADR de seleção. | J41: Executar busca híbrida no app com apenas o backend escolhido instalado. | K41: SL-S40-GATE | L41: Crítico | N41: =COUNTIFS(Tarefas!$D$2:$D$793,A41,Tarefas!$G$2:$G$793,"<>Gate",Tarefas!$X$2:$X$793,"OK") | O41: 10 | P41: =COUNTIFS(Tarefas!$D$2:$D$793,A41,Tarefas!$G$2:$G$793,"<>Gate",Tarefas!$X$2:$X$793,"DISPENSADO") | Q41: =IFERROR(N41/(O41-P41),0)
A42: S41 | B42: v0.7.0 | C42: Entregar busca incremental no acervo e nas Peças | D42: Fazer recuperação refletir revisões, exclusões e diferentes tipos de autoria. | E42: SearchService / UI | F42: Integração | G42: S35; S40 | H42: R02; R05; R13; R20; R21; R31 | I42: v0.7.0 com busca híbrida e reconstrução assistida. | J42: Editar/excluir material e verificar atualização da busca sem perder as fontes canônicas. | K42: SL-S41-GATE | L42: Crítico | N42: =COUNTIFS(Tarefas!$D$2:$D$793,A42,Tarefas!$G$2:$G$793,"<>Gate",Tarefas!$X$2:$X$793,"OK") | O42: 10 | P42: =COUNTIFS(Tarefas!$D$2:$D$793,A42,Tarefas!$G$2:$G$793,"<>Gate",Tarefas!$X$2:$X$793,"DISPENSADO") | Q42: =IFERROR(N42/(O42-P42),0)
A43: S42 | B43: v0.8.0 | C43: Auditar e recortar PageIndex para células | D43: Identificar código reaproveitável e pontos que precisam perder acoplamento documental/cloud. | E43: PageIndex / upstream | F43: Desconstrução | G43: S03; S23; S32; S41 | H43: R03; R22; R23; R30; R33 | I43: Pacote experimental de contexto e ADR do recorte PageIndex. | J43: Construir índice de Markdown de fixture sem PDF e sem store canônico do SDK. | K43: SL-S42-GATE | L43: Crítico | N43: =COUNTIFS(Tarefas!$D$2:$D$793,A43,Tarefas!$G$2:$G$793,"<>Gate",Tarefas!$X$2:$X$793,"OK") | O43: 10 | P43: =COUNTIFS(Tarefas!$D$2:$D$793,A43,Tarefas!$G$2:$G$793,"<>Gate",Tarefas!$X$2:$X$793,"DISPENSADO") | Q43: =IFERROR(N43/(O43-P43),0)
A44: S43 | B44: v0.8.0 | C44: Projetar a topologia em índice estrutural estável | D44: Transformar workspace/células em hierarquia navegável sem perder o grafo. | E44: PageIndex / StructureAdapter | F44: Adaptação | G44: S17; S42 | H44: R02; R04; R11; R22; R32 | I44: WorkspaceSnapshot e índice estrutural por revisão. | J44: Renomear notas, mover cartões e reconstruir mantendo IDs e referências. | K44: SL-S43-GATE | L44: Alto | N44: =COUNTIFS(Tarefas!$D$2:$D$793,A44,Tarefas!$G$2:$G$793,"<>Gate",Tarefas!$X$2:$X$793,"OK") | O44: 10 | P44: =COUNTIFS(Tarefas!$D$2:$D$793,A44,Tarefas!$G$2:$G$793,"<>Gate",Tarefas!$X$2:$X$793,"DISPENSADO") | Q44: =IFERROR(N44/(O44-P44),0)
A45: S44 | B45: v0.8.0 | C45: Criar ferramentas de contexto com escopo efetivo | D45: Permitir exploração pelo modelo sem lhe entregar o Vault ou a biblioteca global. | E45: ToolBroker / PageIndex | F45: Adaptação | G45: S09; S26; S43 | H45: R06; R08; R22; R23 | I45: Ferramentas de overview, grupo, célula, vizinhos e fonte. | J45: Modelo recebe ID fora do escopo e o broker nega mesmo com instrução em documento. | K45: SL-S44-GATE | L45: Crítico | N45: =COUNTIFS(Tarefas!$D$2:$D$793,A45,Tarefas!$G$2:$G$793,"<>Gate",Tarefas!$X$2:$X$793,"OK") | O45: 10 | P45: =COUNTIFS(Tarefas!$D$2:$D$793,A45,Tarefas!$G$2:$G$793,"<>Gate",Tarefas!$X$2:$X$793,"DISPENSADO") | Q45: =IFERROR(N45/(O45-P45),0)
A46: S45 | B46: v0.8.0 | C46: Implementar summaries incrementais e Skeleton Map | D46: Usar síntese estrutural dentro do contexto dos modelos locais e com invalidação precisa. | E46: ContextService / LocalAI | F46: Próprio | G46: S33; S43; S44 | H46: R09; R19; R22; R23 | I46: Skeleton Map com budget e cache incremental de resumos. | J46: Editar uma célula e recomputar apenas summaries dependentes, sem perder evidências. | K46: SL-S45-GATE | L46: Alto | N46: =COUNTIFS(Tarefas!$D$2:$D$793,A46,Tarefas!$G$2:$G$793,"<>Gate",Tarefas!$X$2:$X$793,"OK") | O46: 10 | P46: =COUNTIFS(Tarefas!$D$2:$D$793,A46,Tarefas!$G$2:$G$793,"<>Gate",Tarefas!$X$2:$X$793,"DISPENSADO") | Q46: =IFERROR(N46/(O46-P46),0)
A47: S46 | B47: v0.8.0 | C47: Entregar recuperação estrutural e síntese progressiva | D47: Fechar o motor da Mesa com evidências, abstenção e limites de execução. | E47: Context Engine / orquestração | F47: Integração | G47: S44; S45 | H47: R07; R13; R22; R23; R27 | I47: v0.8.0: consulta estrutural local sobre células e fontes. | J47: Perguntar sobre grupos que se contradizem e receber resposta apoiada nas revisões corretas. | K47: SL-S46-GATE | L47: Alto | N47: =COUNTIFS(Tarefas!$D$2:$D$793,A47,Tarefas!$G$2:$G$793,"<>Gate",Tarefas!$X$2:$X$793,"OK") | O47: 10 | P47: =COUNTIFS(Tarefas!$D$2:$D$793,A47,Tarefas!$G$2:$G$793,"<>Gate",Tarefas!$X$2:$X$793,"DISPENSADO") | Q47: =IFERROR(N47/(O47-P47),0)
A48: S47 | B48: v0.9.0 | C48: Integrar SearxNG como serviço de descoberta | D48: Usar metabusca sem incorporar sua UI ou criar dependência pública implícita. | E48: SearxNG / WebDiscoveryProvider | F48: Desconstrução | G48: S23; S26; S34; S46 | H48: R08; R24; R30; R33 | I48: Provider SearxNG com configuração, consentimento e testes de resposta. | J48: Pesquisar por consulta autorizada e apresentar resultados sem enviar o board inteiro. | K48: SL-S47-GATE | L48: Crítico | N48: =COUNTIFS(Tarefas!$D$2:$D$793,A48,Tarefas!$G$2:$G$793,"<>Gate",Tarefas!$X$2:$X$793,"OK") | O48: 10 | P48: =COUNTIFS(Tarefas!$D$2:$D$793,A48,Tarefas!$G$2:$G$793,"<>Gate",Tarefas!$X$2:$X$793,"DISPENSADO") | Q48: =IFERROR(N48/(O48-P48),0)
